Traceback (most recent call last):
  File "/Users/karthik/PycharmProjects/BN-WVAD_UCF/main.py", line 106, in <module>
    metric = test(net, test_loader, test_info, 0)
             ^^^^^^^^^^^^^^^^^^^^^^^^^^^^^^^^^^^^
  File "/Users/karthik/PycharmProjects/BN-WVAD_UCF/test.py", line 61, in test
    frame_predicts = get_predicts(test_loader, net)
                     ^^^^^^^^^^^^^^^^^^^^^^^^^^^^^^
  File "/Users/karthik/PycharmProjects/BN-WVAD_UCF/test.py", line 18, in get_predicts
    _data, _label = next(load_iter)
                    ^^^^^^^^^^^^^^^
  File "/Users/karthik/PycharmProjects/video_features/video_features/venv/lib/python3.12/site-packages/torch/utils/data/dataloader.py", line 631, in __next__
    data = self._next_data()
           ^^^^^^^^^^^^^^^^^
  File "/Users/karthik/PycharmProjects/video_features/video_features/venv/lib/python3.12/site-packages/torch/utils/data/dataloader.py", line 1346, in _next_data
    return self._process_data(data)
           ^^^^^^^^^^^^^^^^^^^^^^^^
  File "/Users/karthik/PycharmProjects/video_features/video_features/venv/lib/python3.12/site-packages/torch/utils/data/dataloader.py", line 1372, in _process_data
    data.reraise()
  File "/Users/karthik/PycharmProjects/video_features/video_features/venv/lib/python3.12/site-packages/torch/_utils.py", line 722, in reraise
    raise exception
FileNotFoundError: Caught FileNotFoundError in DataLoader worker process 0.
Original Traceback (most recent call last):
  File "/Users/karthik/PycharmProjects/video_features/video_features/venv/lib/python3.12/site-packages/torch/utils/data/_utils/worker.py", line 308, in _worker_loop
    data = fetcher.fetch(index)
           ^^^^^^^^^^^^^^^^^^^^
  File "/Users/karthik/PycharmProjects/video_features/video_features/venv/lib/python3.12/site-packages/torch/utils/data/_utils/fetch.py", line 51, in fetch
    data = [self.dataset[idx] for idx in possibly_batched_index]
            ~~~~~~~~~~~~^^^^^
  File "/Users/karthik/PycharmProjects/BN-WVAD_UCF/dataset_loader.py", line 123, in __getitem__
    data,label = self.get_data(index)
                 ^^^^^^^^^^^^^^^^^^^^
  File "/Users/karthik/PycharmProjects/BN-WVAD_UCF/dataset_loader.py", line 139, in get_data
    video_feature = np.load(os.path.join(self.feature_path, vid_name)).astype(np.float32)          # (64, t, 1024)
                    ^^^^^^^^^^^^^^^^^^^^^^^^^^^^^^^^^^^^^^^^^^^^^^^^^^
  File "/Users/karthik/PycharmProjects/video_features/video_features/venv/lib/python3.12/site-packages/numpy/lib/npyio.py", line 427, in load
    fid = stack.enter_context(open(os_fspath(file), "rb"))
                              ^^^^^^^^^^^^^^^^^^^^^^^^^^^
FileNotFoundError: [Errno 2] No such file or directory: '/Volumes/KARTUSB/video_data_sets/I3D/Train/RGB/Test/Abuse028_x264.npy'
